<?xml version="1.0" encoding="utf-8"?>
<!-- =================================================================================== -->
<!-- |    This document was autogenerated by xacro from xarm.urdf.xacro                | -->
<!-- |    EDITING THIS FILE BY HAND IS NOT RECOMMENDED                                 | -->
<!-- =================================================================================== -->
<robot name="xarm">
  <gazebo>
    <plugin filename="libgazebo_ros_control.so" name="gazebo_ros_control">
      <!--      <robotNamespace>/xbot2</robotNamespace>-->
      <robotSimType>gazebo_ros_control/DefaultRobotHWSim</robotSimType>
    </plugin>
  </gazebo>
  <link name="world"/>
  <joint name="virtual_joint" type="fixed">
    <parent link="world"/>
    <child link="base_link"/>
    <origin rpy="0.0 0.0 0.0" xyz="0.0 0.0 0.0"/>
  </joint>
  <link name="base_link">
    <inertial>
      <origin rpy="0 0 0" xyz="-0.0170438376621442 -0.00161939260033202 0.0724948120416346"/>
      <mass value="0.553260236209975"/>
      <inertia ixx="0.0026064369657739" ixy="-3.75417322493413E-06" ixz="-0.000130251544119884" iyy="0.0030374528540518" iyz="-6.38538659319183E-05" izz="0.00326639522571418"/>
    </inertial>
    <visual>
      <origin rpy="0 0 0" xyz="0 0 0"/>
      <geometry>
        <mesh filename="package://xarm_description/meshes/base_link.STL"/>
      </geometry>
      <material name="LightGrey">
        <color rgba="0.7 0.7 0.7 1.0"/>
      </material>
    </visual>
    <collision>
      <origin rpy="0 0 0" xyz="0 0 0"/>
      <geometry>
        <mesh filename="package://xarm_description/meshes/base_link.STL"/>
      </geometry>
    </collision>
  </link>
  <link name="arm_1_link">
    <inertial>
      <origin rpy="0 0 0" xyz="-0.000128118597624595 -0.013600859873518 0.0619700515240474"/>
      <mass value="0.116423492746118"/>
      <inertia ixx="0.000383159534984" ixy="2.54107232372875E-07" ixz="-3.85780244490042E-07" iyy="0.000273038903011898" iyz="-3.95745103630226E-05" izz="0.000290856563695735"/>
    </inertial>
    <visual>
      <origin rpy="0 0 0" xyz="0 0 0"/>
      <geometry>
        <mesh filename="package://xarm_description/meshes/arm_link1.STL"/>
      </geometry>
      <material name="">
        <color rgba="0.7 0.7 0.7 1.0"/>
      </material>
    </visual>
    <collision>
      <origin rpy="0 0 0" xyz="0 0 0"/>
      <geometry>
        <mesh filename="package://xarm_description/meshes/arm_link1.STL"/>
      </geometry>
    </collision>
  </link>
  <joint name="arm_1_joint" type="revolute">
    <origin rpy="0 0 0" xyz="0 0 0.1398"/>
    <parent link="base_link"/>
    <child link="arm_1_link"/>
    <axis xyz="0 0 -1"/>
    <limit effort="100" lower="-1.570796327" upper="1.570796327" velocity="0.35"/>
    <dynamics damping="1.0" friction="1.0"/>
  </joint>
  <link name="arm_2_link">
    <inertial>
      <origin rpy="0 0 0" xyz="-0.0167470721830778 0.0837012292062612 0.0494160246373337"/>
      <mass value="0.13106183966175"/>
      <inertia ixx="0.000452532131006666" ixy="1.7225875446078E-05" ixz="-5.65576192946032E-07" iyy="0.000314237741777992" iyz="3.03456757973936E-07" izz="0.000368104794036537"/>
    </inertial>
    <visual>
      <origin rpy="0 0 0" xyz="0 0 0"/>
      <geometry>
        <mesh filename="package://xarm_description/meshes/arm_link2.STL"/>
      </geometry>
      <material name="">
        <color rgba="0.7 0.75 0.7 1.0"/>
      </material>
    </visual>
    <collision>
      <origin rpy="0 0 0" xyz="0 0 0"/>
      <geometry>
        <mesh filename="package://xarm_description/meshes/arm_link2.STL"/>
      </geometry>
    </collision>
  </link>
  <joint name="arm_2_joint" type="revolute">
    <origin rpy="1.5708 0 0" xyz="0 0.05 0.095"/>
    <parent link="arm_1_link"/>
    <child link="arm_2_link"/>
    <axis xyz="0 0 1"/>
    <limit effort="100" lower="-1.92" upper="1.4" velocity="0.35"/>
    <dynamics damping="1.0" friction="1.0"/>
  </joint>
  <link name="arm_3_link">
    <inertial>
      <origin rpy="0 0 0" xyz="8.14220214549778E-05 -2.55521254908583E-05 0.0513480682450201"/>
      <mass value="0.086404289942178"/>
      <inertia ixx="0.00019238332088768" ixy="9.37345781486257E-10" ixz="-9.86128909629744E-07" iyy="0.000179094376632573" iyz="5.16398573265577E-08" izz="0.000133516037906134"/>
    </inertial>
    <visual>
      <origin rpy="0 0 0" xyz="0 0 0"/>
      <geometry>
        <mesh filename="package://xarm_description/meshes/arm_link3.STL"/>
      </geometry>
      <material name="">
        <color rgba="0.7 0.7 0.7 1.0"/>
      </material>
    </visual>
    <collision>
      <origin rpy="0 0 0" xyz="0 0 0"/>
      <geometry>
        <mesh filename="package://xarm_description/meshes/arm_link3.STL"/>
      </geometry>
    </collision>
  </link>
  <joint name="arm_3_joint" type="revolute">
    <origin rpy="-1.5708 0 0" xyz="-0.0185 0.145 0.0495"/>
    <parent link="arm_2_link"/>
    <child link="arm_3_link"/>
    <axis xyz="0 0 -1"/>
    <limit effort="100" lower="-2" upper="2" velocity="0.35"/>
    <dynamics damping="1.0" friction="1.0"/>
  </joint>
  <link name="arm_4_link">
    <inertial>
      <origin rpy="0 0 0" xyz="-0.000397266371060974 0.0598499691331028 0.0332505816207749"/>
      <mass value="0.0706309208099729"/>
      <inertia ixx="0.000125455196294012" ixy="4.89969471646502E-07" ixz="1.48744519872573E-11" iyy="9.24064014654882E-05" iyz="-1.65705397681498E-09" izz="0.00010157515036857"/>
    </inertial>
    <visual>
      <origin rpy="0 0 0" xyz="0 0 0"/>
      <geometry>
        <mesh filename="package://xarm_description/meshes/arm_link4.STL"/>
      </geometry>
      <material name="">
        <color rgba="0.7 0.7 0.7 1.0"/>
      </material>
    </visual>
    <collision>
      <origin rpy="0 0 0" xyz="0 0 0"/>
      <geometry>
        <mesh filename="package://xarm_description/meshes/arm_link4.STL"/>
      </geometry>
    </collision>
  </link>
  <joint name="arm_4_joint" type="revolute">
    <origin rpy="1.5708 0 0" xyz="0.0005 0.033 0.105"/>
    <parent link="arm_3_link"/>
    <child link="arm_4_link"/>
    <axis xyz="0 0 1"/>
    <limit effort="100" lower="-1.57" upper="1.57" velocity="0.35"/>
    <dynamics damping="1.0" friction="1.0"/>
  </joint>
  <link name="arm_5_link">
    <inertial>
      <origin rpy="0 0 0" xyz="-0.000727167883412056 1.56292209022133E-07 0.0448838742871538"/>
      <mass value="0.0364674809635235"/>
      <inertia ixx="4.04278205884715E-05" ixy="-4.07023183502984E-11" ixz="4.60079695225723E-07" iyy="4.23703736642409E-05" iyz="-1.25762158698788E-11" izz="2.78990988682426E-05"/>
    </inertial>
    <visual>
      <origin rpy="0 0 0" xyz="0 0 0"/>
      <geometry>
        <mesh filename="package://xarm_description/meshes/arm_link5.STL"/>
      </geometry>
      <material name="">
        <color rgba="0.7 0.75 0.7 1.0"/>
      </material>
    </visual>
    <collision>
      <origin rpy="0 0 0" xyz="0 0 0"/>
      <geometry>
        <mesh filename="package://xarm_description/meshes/arm_link5.STL"/>
      </geometry>
      <material name="">
        <color rgba="0.7 0.75 0.7 1.0"/>
      </material>
    </collision>
  </link>
  <joint name="arm_5_joint" type="revolute">
    <origin rpy="-1.5708 0 -0.004902" xyz="0.00051471 0.105 0.03325"/>
    <parent link="arm_4_link"/>
    <child link="arm_5_link"/>
    <axis xyz="0 0 -1"/>
    <limit effort="100" lower="-2" upper="2" velocity="0.35"/>
    <dynamics damping="1.0" friction="1.0"/>
  </joint>
  <link name="arm_6_link">
    <inertial>
      <origin rpy="0 0 0" xyz="0.00213188955016766 0.0459939849274835 0.0209144934053668"/>
      <mass value="0.0283301622794919"/>
      <inertia ixx="3.08264693220698E-05" ixy="-4.86665976397017E-07" ixz="1.45743977499393E-07" iyy="2.03804574554996E-05" iyz="4.96221959166978E-08" izz="2.47043306516181E-05"/>
    </inertial>
    <visual>
      <origin rpy="0 0 0" xyz="0 0 0"/>
      <geometry>
        <mesh filename="package://xarm_description/meshes/arm_link6.STL"/>
      </geometry>
      <material name="">
        <color rgba="0.7 0.7 0.7 1.0"/>
      </material>
    </visual>
    <collision>
      <origin rpy="0 0 0" xyz="0 0 0"/>
      <geometry>
        <mesh filename="package://xarm_description/meshes/arm_link6.STL"/>
      </geometry>
    </collision>
  </link>
  <joint name="arm_6_joint" type="revolute">
    <origin rpy="1.5708 -0.004902 0" xyz="0 0.0215 0.075"/>
    <parent link="arm_5_link"/>
    <child link="arm_6_link"/>
    <axis xyz="0 0 1"/>
    <limit effort="100" lower="-1.57" upper="0.52" velocity="0.35"/>
    <dynamics damping="1.0" friction="1.0"/>
  </joint>
  <link name="gripper_1_link">
    <inertial>
      <origin rpy="0 0 0" xyz="-0.010164529829209 -0.0428625582773113 -0.0290009634440926"/>
      <mass value="0.0229473565168191"/>
      <inertia ixx="2.67319833363079E-05" ixy="5.28739561760064E-07" ixz="4.53208934357424E-10" iyy="1.30658365460368E-05" iyz="8.86316306994805E-10" izz="1.74706100511411E-05"/>
    </inertial>
    <visual>
      <origin rpy="0 0 0" xyz="0 0 0"/>
      <geometry>
        <mesh filename="package://xarm_description/meshes/gipper_link1.STL"/>
      </geometry>
      <material name="">
        <color rgba="1 1 1 1"/>
      </material>
    </visual>
    <collision>
      <origin rpy="0 0 0" xyz="0 0 0"/>
      <geometry>
        <mesh filename="package://xarm_description/meshes/gipper_link1.STL"/>
      </geometry>
    </collision>
  </link>
  <joint name="gripper_1_joint" type="revolute">
    <origin rpy="3.1367 1.5708 0" xyz="-0.029493 0.062645 0.03295"/>
    <parent link="arm_6_link"/>
    <child link="gripper_1_link"/>
    <axis xyz="0 0 -1"/>
    <limit effort="20" lower="0" upper="0.7" velocity="0.35"/>
    <dynamics damping="1.0" friction="1.0"/>
  </joint>
  <link name="gripper_2_link">
    <inertial>
      <origin rpy="0 0 0" xyz="-0.0101244857399807 -0.0426966769105175 0.0289990675316095"/>
      <mass value="0.0230365589670101"/>
      <inertia ixx="2.69624656070297E-05" ixy="4.89378228982721E-07" ixz="4.53308989647818E-10" iyy="1.31475134895181E-05" iyz="9.01986586877508E-10" izz="1.76482216371948E-05"/>
    </inertial>
    <visual>
      <origin rpy="0 0 0" xyz="0 0 0"/>
      <geometry>
        <mesh filename="package://xarm_description/meshes/gipper_link2.STL"/>
      </geometry>
      <material name="">
        <color rgba="1 1 1 1"/>
      </material>
    </visual>
    <collision>
      <origin rpy="0 0 0" xyz="0 0 0"/>
      <geometry>
        <mesh filename="package://xarm_description/meshes/gipper_link2.STL"/>
      </geometry>
    </collision>
  </link>
  <joint name="gripper_2_joint" type="revolute">
    <origin rpy="3.14159 -1.5708 0" xyz="-0.029493 0.062645 0.00945"/>
    <parent link="arm_6_link"/>
    <child link="gripper_2_link"/>
    <axis xyz="0 0 -1"/>
    <limit effort="20" lower="0" upper="0.7" velocity="0.35"/>
    <dynamics damping="1.0" friction="1.0"/>
  </joint>
  <link name="gripper_centor_link">
  </link>
  <joint name="gripper_centor_joint" type="fixed">
    <origin rpy="3.1416 1.5708 0" xyz="-0.0001869 0.12514 0.0212"/>
    <parent link="arm_6_link"/>
    <child link="gripper_centor_link"/>
    <axis xyz="0 0 0"/>
  </joint>
  <transmission name="arm_1_trans">
    <type>transmission_interface/SimpleTransmission</type>
    <actuator name="arm_1_motor">
      <mechanicalReduction>1.0</mechanicalReduction>
    </actuator>
    <joint name="arm_1_joint">
      <offset>0.0</offset>
      <hardwareInterface>hardware_interface/PositionJointInterface</hardwareInterface>
      <!--        <hardwareInterface>hardware_interface/EffortJointInterface</hardwareInterface>-->
      <!--        <hardwareInterface>hardware_interface/JointStateInterface</hardwareInterface>-->
    </joint>
  </transmission>
  <transmission name="arm_2_trans">
    <type>transmission_interface/SimpleTransmission</type>
    <actuator name="arm_2_motor">
      <mechanicalReduction>1.0</mechanicalReduction>
    </actuator>
    <joint name="arm_2_joint">
      <offset>0.0</offset>
      <hardwareInterface>hardware_interface/PositionJointInterface</hardwareInterface>
      <!--        <hardwareInterface>hardware_interface/EffortJointInterface</hardwareInterface>-->
      <!--        <hardwareInterface>hardware_interface/JointStateInterface</hardwareInterface>-->
    </joint>
  </transmission>
  <transmission name="arm_3_trans">
    <type>transmission_interface/SimpleTransmission</type>
    <actuator name="arm_3_motor">
      <mechanicalReduction>1.0</mechanicalReduction>
    </actuator>
    <joint name="arm_3_joint">
      <offset>0.0</offset>
      <hardwareInterface>hardware_interface/PositionJointInterface</hardwareInterface>
      <!--        <hardwareInterface>hardware_interface/EffortJointInterface</hardwareInterface>-->
      <!--        <hardwareInterface>hardware_interface/JointStateInterface</hardwareInterface>-->
    </joint>
  </transmission>
  <transmission name="arm_4_trans">
    <type>transmission_interface/SimpleTransmission</type>
    <actuator name="arm_4_motor">
      <mechanicalReduction>1.0</mechanicalReduction>
    </actuator>
    <joint name="arm_4_joint">
      <offset>0.0</offset>
      <hardwareInterface>hardware_interface/PositionJointInterface</hardwareInterface>
      <!--        <hardwareInterface>hardware_interface/EffortJointInterface</hardwareInterface>-->
      <!--        <hardwareInterface>hardware_interface/JointStateInterface</hardwareInterface>-->
    </joint>
  </transmission>
  <transmission name="arm_5_trans">
    <type>transmission_interface/SimpleTransmission</type>
    <actuator name="arm_5_motor">
      <mechanicalReduction>1.0</mechanicalReduction>
    </actuator>
    <joint name="arm_5_joint">
      <offset>0.0</offset>
      <hardwareInterface>hardware_interface/PositionJointInterface</hardwareInterface>
      <!--        <hardwareInterface>hardware_interface/EffortJointInterface</hardwareInterface>-->
      <!--        <hardwareInterface>hardware_interface/JointStateInterface</hardwareInterface>-->
    </joint>
  </transmission>
  <transmission name="arm_6_trans">
    <type>transmission_interface/SimpleTransmission</type>
    <actuator name="arm_6_motor">
      <mechanicalReduction>1.0</mechanicalReduction>
    </actuator>
    <joint name="arm_6_joint">
      <offset>0.0</offset>
      <hardwareInterface>hardware_interface/PositionJointInterface</hardwareInterface>
      <!--        <hardwareInterface>hardware_interface/EffortJointInterface</hardwareInterface>-->
      <!--        <hardwareInterface>hardware_interface/JointStateInterface</hardwareInterface>-->
    </joint>
  </transmission>
  <transmission name="gripper_1_trans">
    <type>transmission_interface/SimpleTransmission</type>
    <actuator name="gripper_1_motor">
      <mechanicalReduction>1.0</mechanicalReduction>
    </actuator>
    <joint name="gripper_1_joint">
      <offset>0.0</offset>
      <hardwareInterface>hardware_interface/PositionJointInterface</hardwareInterface>
      <!--        <hardwareInterface>hardware_interface/EffortJointInterface</hardwareInterface>-->
      <!--        <hardwareInterface>hardware_interface/JointStateInterface</hardwareInterface>-->
    </joint>
  </transmission>
  <transmission name="gripper_2_trans">
    <type>transmission_interface/SimpleTransmission</type>
    <actuator name="gripper_2_motor">
      <mechanicalReduction>1.0</mechanicalReduction>
    </actuator>
    <joint name="gripper_2_joint">
      <offset>0.0</offset>
      <hardwareInterface>hardware_interface/PositionJointInterface</hardwareInterface>
      <!--        <hardwareInterface>hardware_interface/EffortJointInterface</hardwareInterface>-->
      <!--        <hardwareInterface>hardware_interface/JointStateInterface</hardwareInterface>-->
    </joint>
  </transmission>
  <gazebo reference="arm_1_link">
    <mu1>0.9</mu1>
    <mu2>0.9</mu2>
    <material>Gazebo/DarkGrey</material>
  </gazebo>
  <gazebo reference="arm_1_joint">
    <implicitSpringDamper>1</implicitSpringDamper>
  </gazebo>
  <gazebo reference="arm_2_link">
    <mu1>0.9</mu1>
    <mu2>0.9</mu2>
    <material>Gazebo/DarkGrey</material>
  </gazebo>
  <gazebo reference="arm_2_joint">
    <implicitSpringDamper>1</implicitSpringDamper>
  </gazebo>
  <gazebo reference="arm_3_link">
    <mu1>0.9</mu1>
    <mu2>0.9</mu2>
    <material>Gazebo/DarkGrey</material>
  </gazebo>
  <gazebo reference="arm_3_joint">
    <implicitSpringDamper>1</implicitSpringDamper>
  </gazebo>
  <gazebo reference="arm_4_link">
    <mu1>0.9</mu1>
    <mu2>0.9</mu2>
    <material>Gazebo/DarkGrey</material>
  </gazebo>
  <gazebo reference="arm_4_joint">
    <implicitSpringDamper>1</implicitSpringDamper>
  </gazebo>
  <gazebo reference="arm_5_link">
    <mu1>0.9</mu1>
    <mu2>0.9</mu2>
    <material>Gazebo/DarkGrey</material>
  </gazebo>
  <gazebo reference="arm_5_joint">
    <implicitSpringDamper>1</implicitSpringDamper>
  </gazebo>
  <gazebo reference="arm_6_link">
    <mu1>0.9</mu1>
    <mu2>0.9</mu2>
    <material>Gazebo/DarkGrey</material>
  </gazebo>
  <gazebo reference="arm_6_joint">
    <implicitSpringDamper>1</implicitSpringDamper>
  </gazebo>
  <gazebo reference="gripper_1_link">
    <mu1>0.9</mu1>
    <mu2>0.9</mu2>
    <material>Gazebo/DarkGrey</material>
  </gazebo>
  <gazebo reference="gripper_1_joint">
    <implicitSpringDamper>1</implicitSpringDamper>
  </gazebo>
  <gazebo reference="gripper_2_link">
    <mu1>0.9</mu1>
    <mu2>0.9</mu2>
    <material>Gazebo/DarkGrey</material>
  </gazebo>
  <gazebo reference="gripper_2_joint">
    <implicitSpringDamper>1</implicitSpringDamper>
  </gazebo>
</robot>
